<?xml version="1.0" encoding="UTF-8" standalone="no"?>
<?pydev-testrun version="1.0"?><pydev-testsuite>
    <summary errors="1" failures="0" finished="true" name="Test Run: 65" tests="1" total_time="Finished in: 0.00 secs."/>
    <test location="/Users/jeff/Documents/workspaces/dme/track_logger_converter/tests/parsers/nmea_parser_test.py" status="error" test="NmeaParserTest.test_rmc_1" time="">
        <stdout/>
        <stderr>
            <![CDATA[Traceback (most recent call last):
  File "/Users/jeff/Documents/workspaces/dme/track_logger_converter/tests/parsers/nmea_parser_test.py", line 19, in test_rmc_1
    test_extractor.extractData(test_fields, NmeaParserTest.test_state)
  File "/Users/jeff/Documents/workspaces/dme/track_logger_converter/parsers/nmea_parser.py", line 35, in extractData
    state.set_data_time(DataState.names[DataState.names.Heading], gps_heading)
AttributeError: 'DataState' object has no attribute 'set_data_time'
]]>
        </stderr>
    </test>
    <launch mode="run">
        <launch_memento>
            <![CDATA[<?xml version="1.0" encoding="UTF-8" standalone="no"?>
<launchConfiguration local="true" path="track_logger_converter nmea_parser_test.py"/>
]]>
        </launch_memento>
    </launch>
</pydev-testsuite>
