<?xml version="1.0" encoding="UTF-8" standalone="no"?>
<?pydev-testrun version="1.0"?><pydev-testsuite>
    <summary errors="1" failures="0" finished="true" name="Test Run: 13" tests="1" total_time="Finished in: 0.00 secs."/>
    <test location="/Users/jeff/Documents/workspaces/dme/track_logger_converter/tests/parsers/can_frame_parser_test.py" status="error" test="CanFrameParserTest.testFrame242" time="">
        <stdout>
            <![CDATA[Clutch: 0
RPM: 0
ECU_THROTTLE: 0
]]>
        </stdout>
        <stderr>
            <![CDATA[Traceback (most recent call last):
  File "/Users/jeff/Documents/workspaces/dme/track_logger_converter/tests/parsers/can_frame_parser_test.py", line 20, in testFrame242
    self.assertEqual(0, self.test_state.get_data_item(DataState.get_data_name_at_idx(DataState.names.Time)), 'Time was not parsed correctly.')
TypeError: get_data_name_at_idx() takes exactly 2 arguments (1 given)
]]>
        </stderr>
    </test>
    <launch mode="run">
        <launch_memento>
            <![CDATA[<?xml version="1.0" encoding="UTF-8" standalone="no"?>
<launchConfiguration local="true" path="track_logger_converter can_frame_parser_test.py"/>
]]>
        </launch_memento>
    </launch>
</pydev-testsuite>
