<?xml version="1.0" encoding="UTF-8" standalone="no"?>
<?pydev-testrun version="1.0"?><pydev-testsuite>
    <summary errors="0" failures="1" finished="true" name="Test Run: 71" tests="1" total_time="Finished in: 0.00 secs."/>
    <test location="/Users/jeff/Documents/workspaces/dme/track_logger_converter/tests/parsers/nmea_parser_test.py" status="fail" test="NmeaParserTest.test_rmc_1" time="">
        <stdout/>
        <stderr>
            <![CDATA[Traceback (most recent call last):
  File "/Users/jeff/Documents/workspaces/dme/track_logger_converter/tests/parsers/nmea_parser_test.py", line 24, in test_rmc_1
    self.assertEqual(0, self.test_state.get_data_item(DataState.get_data_name_at_idx(DataState.names.GPS_Date)), '2019-05-19')
AssertionError: 0 != '2019-05-19' : 2019-05-19
]]>
        </stderr>
    </test>
    <launch mode="run">
        <launch_memento>
            <![CDATA[<?xml version="1.0" encoding="UTF-8" standalone="no"?>
<launchConfiguration local="true" path="track_logger_converter nmea_parser_test.py"/>
]]>
        </launch_memento>
    </launch>
</pydev-testsuite>
